<?xml version="1.0" ?>
<!-- =================================================================================== -->
<!-- |    This document was autogenerated by xacro from /home/ashish/s3_ws/install/s3_description/share/s3_description/urdf/s3.urdf.xacro | -->
<!-- |    EDITING THIS FILE BY HAND IS NOT RECOMMENDED                                 | -->
<!-- =================================================================================== -->
<robot name="snake_robot">
  <!-- Include Gazebo Parameters -->
  <!-- <xacro:include filename="$(find s3_description)/urdf/s3_gazebo.xacro" /> -->
  <gazebo>
    <plugin filename="libgazebo_ros2_control.so" name="gazebo_ros2_control">
      <robot_param>robot_description</robot_param>
      <robot_param_node>robot_state_publisher</robot_param_node>
      <parameters>/home/ashish/s3_ws/install/s3_controller/share/s3_controller/config/s3_controllers.yaml</parameters>
    </plugin>
  </gazebo>
  <!-- Include ros2_control Plugins -->
  <!-- <xacro:include filename="$(find s3_description)/urdf/s3_ros2_control.xacro" /> -->
  <ros2_control name="RobotSystem" type="system">
    <!-- ros2_control Gazebo -->
    <hardware>
      <plugin>gazebo_ros2_control/GazeboSystem</plugin>
    </hardware>
    <joint name="joint_1">
      <command_interface name="position">
        <param name="min">-1.570796326795</param>
        <param name="max">1.570796326795</param>
      </command_interface>
      <state_interface name="position"/>
    </joint>
    <joint name="joint_2">
      <command_interface name="position">
        <param name="min">-1.570796326795</param>
        <param name="max">1.570796326795</param>
      </command_interface>
      <state_interface name="position"/>
    </joint>
  </ros2_control>
  <!-- Base Link -->
  <link name="base_link"/>
  <!-- Link 1 -->
  <link name="link1">
    <inertial>
      <origin rpy="0 0 0" xyz="0.2 0 0.05"/>
      <mass value="0.1"/>
      <inertia ixx="1.0" ixy="0.0" ixz="0.0" iyy="1.0" iyz="0.0" izz="1.0"/>
    </inertial>
    <visual>
      <origin rpy="0 0 0" xyz="0.2 0 0.05"/>
      <geometry>
        <box size="0.4 0.1 0.1"/>
        <!-- Length, Width, Height -->
      </geometry>
      <material name="blue">
        <color rgba="0 0 1 1"/>
      </material>
    </visual>
    <collision>
      <origin rpy="0 0 0" xyz="0.2 0 0.05"/>
      <geometry>
        <box size="0.4 0.1 0.1"/>
        <!-- Length, Width, Height -->
      </geometry>
    </collision>
  </link>
  <!-- Link 2 -->
  <link name="link2">
    <inertial>
      <origin rpy="0 0 0" xyz="0.2 0 0.05"/>
      <mass value="0.1"/>
      <inertia ixx="1.0" ixy="0.0" ixz="0.0" iyy="1.0" iyz="0.0" izz="1.0"/>
    </inertial>
    <visual>
      <origin rpy="0 0 0" xyz="0.2 0 0.05"/>
      <geometry>
        <box size="0.4 0.1 0.1"/>
        <!-- Length, Width, Height -->
      </geometry>
      <material name="green">
        <color rgba="0 1 0 1"/>
      </material>
    </visual>
    <collision>
      <origin rpy="0 0 0" xyz="0.2 0 0.05"/>
      <geometry>
        <box size="0.4 0.1 0.1"/>
        <!-- Length, Width, Height -->
      </geometry>
    </collision>
  </link>
  <!-- Link 3 -->
  <link name="link3">
    <inertial>
      <origin rpy="0 0 0" xyz="0.2 0 0.05"/>
      <mass value="0.1"/>
      <inertia ixx="1.0" ixy="0.0" ixz="0.0" iyy="1.0" iyz="0.0" izz="1.0"/>
    </inertial>
    <visual>
      <origin rpy="0 0 0" xyz="0.2 0 0.05"/>
      <geometry>
        <box size="0.4 0.1 0.1"/>
        <!-- Length, Width, Height -->
      </geometry>
      <material name="red">
        <color rgba="1 0 0 1"/>
      </material>
    </visual>
    <collision>
      <origin rpy="0 0 0" xyz="0.2 0 0.05"/>
      <geometry>
        <box size="0.4 0.1 0.1"/>
        <!-- Length, Width, Height -->
      </geometry>
    </collision>
  </link>
  <!-- Joint 0: Between Base Link and Link 1 -->
  <joint name="joint0" type="fixed">
    <parent link="base_link"/>
    <child link="link1"/>
    <origin rpy="0 0 0" xyz="0 0 0"/>
  </joint>
  <!-- Joint 1: Between Link 1 and Link 2 -->
  <joint name="joint_1" type="revolute">
    <parent link="link1"/>
    <child link="link2"/>
    <origin rpy="0 0 0" xyz="0.4 0 0"/>
    <axis xyz="0 0 1"/>
    <!-- Rotation around Z-axis -->
    <limit effort="30" lower="-1.570796326795" upper="1.570796326795" velocity="10"/>
  </joint>
  <!-- Joint 2: Between Link 2 and Link 3 -->
  <joint name="joint_2" type="revolute">
    <parent link="link2"/>
    <child link="link3"/>
    <origin rpy="0 0 0" xyz="0.4 0 0"/>
    <axis xyz="0 0 1"/>
    <!-- Rotation around Z-axis -->
    <limit effort="30" lower="-1.570796326795" upper="1.570796326795" velocity="10"/>
  </joint>
  <transmission name="transmission_1">
    <plugin>transmission_interface/SimpleTransmission</plugin>
    <actuator name="motor_1" role="actuator1"/>
    <joint name="joint_1" role="joint1">
      <mechanical_reduction>1.0</mechanical_reduction>
    </joint>
  </transmission>
  <transmission name="transmission_2">
    <plugin>transmission_interface/SimpleTransmission</plugin>
    <actuator name="motor_2" role="actuator1"/>
    <joint name="joint_2" role="joint1">
      <mechanical_reduction>1.0</mechanical_reduction>
    </joint>
  </transmission>
</robot>
